Workbook

Sheet Audit Raw data
AW1: 6 | AX1: 4 | AY1: 4 | AZ1: 2 | BA1: 4 | BB1: 4 | BC1: 4 | BD1: 2 | BE1: 4 | BF1: 2 | BG1: 4 | BH1: 4 | BI1: 4 | BJ1: 2 | BK1: 4 | BL1: 2 | BM1: 4 | BN1: 4 | BO1: 4 | BP1: 4 | BQ1: 6 | BR1: 4 | BS1: 4 | BT1: 4 | BU1: 4 | BW1: 6 | BZ1: =SUM(AW1:BY1) -> 100
A2: Timestamp | B2: Email Address | C2: Score | D2: Auditor Name | E2: Audit Date | F2: LOB | G2: Call Date | H2: Mobile Number | I2: Duration Of Call | J2: Agent Emp ID | K2: Call Language | L2: Circle of Call | M2: Greeted Customer, Started BSNL Name, Started Call with a Smile | N2: Introduced Self (First Name) | O2: Asked Caller Name(First &Last name) | P2: Asked the Caller required Verification Question (If any) | Q2: Asked caller the purpose of the call | R2: Verified the Purpose of the caller (Paraphrase) | S2: Identified the call type & Identified the process to be followed | T2: Identified the IT Systems/tools to be used | U2: Followed all Process Steps/ Actives in Sequence ? | V2: Navigated the System Without any errors (Leading to Increase call hold time) | W2: Procure the required information from customer | X2: Utilized all information & System access before escalation | Y2: Used Approved Question/Polite language | Z2: Demonstrated active listening skills | AA2: Used confidence & empathy Wordings | AB2: Gave apology/reassurance/appropriate response | AC2: Explained hold time or Dead air | AD2: Upheld BSNL positive image | AE2: Maintained focus on caller's problem | AF2: Identified other issues raised (if any) during the call & Sequenced each issue | AG2: Give accurate information/ Next steps on each issue | AH2: Transferred call appropriately (if required) | AI2: Gave SR Number (If applicable) | AJ2: Thanked the caller for calling | AK2: Waited for caller to hangup and appropriately closed the call ? | AL2: Script adherence | AM2: Captured accurate notes in the CRM | AN2: Captured proper Notes | AO2: Tagging Accuracy | AP2: What went wrong ,required for Agent Feedback | AQ2: Call Summary | AR2: Type of Connection | AS2: Type of call | AT2: Sub Type of Call | AU2: Issues forund on call | AW2: Greeted Customer, Started BSNL Name, Started Call with a Smile | AX2: Introduced Self (First Name) | AY2: Asked Caller Name(First &Last name) | AZ2: Asked the Caller required Verification Question (If any) | BA2: Asked caller the purpose of the call | BB2: Verified the Purpose of the caller (Paraphrase) | BC2: Identified the call type & Identified the process to be followed | BD2: Identified the IT Systems/tools to be used | BE2: Followed all Process Steps/ Actives in Sequence ? | BF2: Navigated the System Without any errors (Leading to Increase call hold time) | BG2: Procure the required information from customer | BH2: Utilized all information & System access before escalation | BI2: Used Approved Question/Polite language | BJ2: Demonstrated active listening skills | BK2: Used confidence & empathy Wordings | BL2: Gave apology/reassurance/appropriate response | BM2: Explained hold time or Dead air | BN2: Upheld BSNL positive image | BO2: Maintained focus on caller's problem | BP2: Identified other issues raised (if any) during the call & Sequenced each issue | BQ2: Give accurate information/ Next steps on each issue | BR2: Transferred call appropriately (if required) | BS2: Gave SR Number (If applicable) | BT2: Thanked the caller for calling | BU2: Waited for caller to hangup and appropriately closed the call ? | BV2: Script adherence | BW2: Captured accurate notes in the CRM | BX2: Captured proper Notes | BY2: Tagging Accuracy | BZ2: SCORE | CA2: TL | CB2: Date | CC2: Quality status
A3: 45667.455 | B3: sshinyc117@gmail.com | C3: 0 / 40 | D3: Shiny | E3: 45931 | F3: Wireless | G3: 9/30/2025 | H3: 9496826734 | I3: 220 | J3: SBM150 | K3: Malayalam | L3: Kerala | M3: Yes | N3: Yes | O3: Yes | P3: Yes | Q3: Yes | R3: No | S3: Yes | T3: Yes | U3: Yes | V3: Yes | W3: Yes | X3: Yes | Y3: Yes | Z3: Yes | AA3: Yes | AB3: Yes | AC3: Not Applicable | AD3: Yes | AE3: No | AF3: Not Applicable | AG3: Yes | AH3: Not Applicable | AI3: Not Applicable | AJ3: Yes | AK3: Not Applicable | AL3: No | AM3: No | AN3: Yes | AO3: Yes | AP3: Complete probing not done, interruption, correct remark not mentioned | AQ3: Customer having network connectivity issue. Advisor complete probing to customer as per call and register complaint for weak signal issue. | AR3: Prepaid | AS3: NETWORK | AT3: POOR NETWORK COVERAGE | AW3: =IF(OR(M3="YES", M3="Not Applicable"), AW$1, "0") -> 6 | AX3: =IF(OR(N3="YES", N3="Not Applicable"), AX$1, "0") -> 4 | AY3: =IF(OR(O3="YES", O3="Not Applicable"), AY$1, "0") -> 4 | AZ3: =IF(OR(P3="YES", P3="Not Applicable"), AZ$1, "0") -> 2 | BA3: =IF(OR(Q3="YES", Q3="Not Applicable"), BA$1, "0") -> 4 | BB3: =IF(OR(R3="YES", R3="Not Applicable"), BB$1, "0") -> 0 | BC3: =IF(OR(S3="YES", S3="Not Applicable"), BC$1, "0") -> 4 | BD3: =IF(OR(T3="YES", T3="Not Applicable"), BD$1, "0") -> 2 | ... BY3: =IF(OR(AO3="YES", AO3="Not Applicable"), BY$1, "0") -> 0 | BZ3: =SUM(AW3:BY3) -> 86 | CA3: =VLOOKUP(J:J,'Agent wise'!A:C,3,0) -> Saran S | CB3: =INT(E3) -> 45931 | CC3: =IF(BZ3>=94.5, "Excellent", IF(BZ3>89.5, "Good", IF(BZ3>84.5, "Average", "FC"))) -> Average | CJ3: =DAY(E3) -> 1 | CK3: =MONTH(E3) -> 10 | CL3: =YEAR(E3) -> 2025
A4: 45667.46 | B4: sshinyc117@gmail.com | C4: 0 / 40 | D4: Shiny | E4: 45931 | F4: Wireless | G4: 9/30/2025 | H4: 9048626079 | I4: 148 | J4: SBM157 | K4: Malayalam | L4: Kerala | M4: Yes | N4: Yes | O4: Yes | P4: Yes | Q4: Yes | R4: No | S4: Yes | T4: Yes | U4: Yes | V4: Yes | W4: Yes | X4: Yes | Y4: Yes | Z4: Yes | AA4: Yes | AB4: Yes | AC4: Not Applicable | AD4: Yes | AE4: Yes | AF4: Yes | AG4: Yes | AH4: Not Applicable | AI4: No | AJ4: Yes | AK4: Not Applicable | AL4: No | AM4: Yes | AN4: Yes | AO4: Yes | AP4: Complete probing not done | AQ4: Customer having call and data connectivity issue. Advisor complete probing to customer as per call and register complaint for weak signal issue , | AR4: Prepaid | AS4: NETWORK | AT4: POOR NETWORK COVERAGE | AW4: =IF(OR(M4="YES", M4="Not Applicable"), AW$1, "0") -> 6 | AX4: =IF(OR(N4="YES", N4="Not Applicable"), AX$1, "0") -> 4 | AY4: =IF(OR(O4="YES", O4="Not Applicable"), AY$1, "0") -> 4 | AZ4: =IF(OR(P4="YES", P4="Not Applicable"), AZ$1, "0") -> 2 | BA4: =IF(OR(Q4="YES", Q4="Not Applicable"), BA$1, "0") -> 4 | BB4: =IF(OR(R4="YES", R4="Not Applicable"), BB$1, "0") -> 0 | BC4: =IF(OR(S4="YES", S4="Not Applicable"), BC$1, "0") -> 4 | BD4: =IF(OR(T4="YES", T4="Not Applicable"), BD$1, "0") -> 2 | ... BY4: =IF(OR(AO4="YES", AO4="Not Applicable"), BY$1, "0") -> 0 | BZ4: =SUM(AW4:BY4) -> 92 | CA4: =VLOOKUP(J:J,'Agent wise'!A:C,3,0) -> Saran S | CB4: =INT(E4) -> 45931 | CC4: =IF(BZ4>=94.5, "Excellent", IF(BZ4>89.5, "Good", IF(BZ4>84.5, "Average", "FC"))) -> Good | CJ4: =DAY(E4) -> 1 | CK4: =MONTH(E4) -> 10 | CL4: =YEAR(E4) -> 2025
A5: 45667.491 | B5: sshinyc117@gmail.com | C5: 0 / 40 | D5: Shiny | E5: 45931 | F5: Wireless | G5: 9/30/2025 | H5: 9445185748 | I5: 217 | J5: SBM363 | K5: Tamil | L5: Tamil Nadu | M5: No | N5: Yes | O5: Yes | P5: Yes | Q5: Yes | R5: No | S5: Yes | T5: Yes | U5: No | V5: Yes | W5: Yes | X5: Yes | Y5: Yes | Z5: Yes | AA5: Yes | AB5: No | AC5: Not Applicable | AD5: Yes | AE5: Yes | AF5: Not Applicable | AG5: Yes | AH5: Not Applicable | AI5: No | AJ5: Yes | AK5: Not Applicable | AL5: No | AM5: Yes | AN5: Yes | AO5: No | AP5: apology missing, correct tagging not done, dead air, complete probing not done | AQ5: Customer having call and data connectivity issue. Advisor complete probing to customer as per call and register complaint for weak signal issue , | AR5: Prepaid | AS5: NETWORK | AT5: POOR VOICE QUALITY | AW5: =IF(OR(M5="YES", M5="Not Applicable"), AW$1, "0") -> 0 | AX5: =IF(OR(N5="YES", N5="Not Applicable"), AX$1, "0") -> 4 | AY5: =IF(OR(O5="YES", O5="Not Applicable"), AY$1, "0") -> 4 | AZ5: =IF(OR(P5="YES", P5="Not Applicable"), AZ$1, "0") -> 2 | BA5: =IF(OR(Q5="YES", Q5="Not Applicable"), BA$1, "0") -> 4 | BB5: =IF(OR(R5="YES", R5="Not Applicable"), BB$1, "0") -> 0 | BC5: =IF(OR(S5="YES", S5="Not Applicable"), BC$1, "0") -> 4 | BD5: =IF(OR(T5="YES", T5="Not Applicable"), BD$1, "0") -> 2 | ... BY5: =IF(OR(AO5="YES", AO5="Not Applicable"), BY$1, "0") -> 0 | BZ5: =SUM(AW5:BY5) -> 80 | CA5: =VLOOKUP(J:J,'Agent wise'!A:C,3,0) -> Saran S | CB5: =INT(E5) -> 45931 | CC5: =IF(BZ5>=94.5, "Excellent", IF(BZ5>89.5, "Good", IF(BZ5>84.5, "Average", "FC"))) -> FC | CJ5: =DAY(E5) -> 1 | CK5: =MONTH(E5) -> 10 | CL5: =YEAR(E5) -> 2025
A6: 45667.494 | B6: sshinyc117@gmail.com | C6: 0 / 40 | D6: Shiny | E6: 45931 | F6: Wireless | G6: 9/30/2025 | H6: 8606790086 | I6: 195 | J6: SBM373 | K6: Malayalam | L6: Kerala | M6: Yes | N6: Yes | O6: Yes | P6: Yes | Q6: Yes | R6: No | S6: Yes | T6: Yes | U6: Yes | V6: Yes | W6: Yes | X6: Yes | Y6: Yes | Z6: Yes | AA6: Yes | AB6: Yes | AC6: No | AD6: Yes | AE6: Yes | AF6: Not Applicable | AG6: Yes | AH6: Not Applicable | AI6: No | AJ6: Yes | AK6: Not Applicable | AL6: No | AM6: Yes | AN6: Yes | AO6: Yes | AP6: Dead air, complete probing not done, further assistance not done | AQ6: Customer having weak signal and data connectivity issue. Advisor complete probing to customer as per call and register complaint for weak signal issue , | AR6: Prepaid | AS6: NETWORK | AT6: NO SIGNAL | AW6: =IF(OR(M6="YES", M6="Not Applicable"), AW$1, "0") -> 6 | AX6: =IF(OR(N6="YES", N6="Not Applicable"), AX$1, "0") -> 4 | AY6: =IF(OR(O6="YES", O6="Not Applicable"), AY$1, "0") -> 4 | AZ6: =IF(OR(P6="YES", P6="Not Applicable"), AZ$1, "0") -> 2 | BA6: =IF(OR(Q6="YES", Q6="Not Applicable"), BA$1, "0") -> 4 | BB6: =IF(OR(R6="YES", R6="Not Applicable"), BB$1, "0") -> 0 | BC6: =IF(OR(S6="YES", S6="Not Applicable"), BC$1, "0") -> 4 | BD6: =IF(OR(T6="YES", T6="Not Applicable"), BD$1, "0") -> 2 | ... BY6: =IF(OR(AO6="YES", AO6="Not Applicable"), BY$1, "0") -> 0 | BZ6: =SUM(AW6:BY6) -> 88 | CA6: =VLOOKUP(J:J,'Agent wise'!A:C,3,0) -> Saran S | CB6: =INT(E6) -> 45931 | CC6: =IF(BZ6>=94.5, "Excellent", IF(BZ6>89.5, "Good", IF(BZ6>84.5, "Average", "FC"))) -> Average | CJ6: =DAY(E6) -> 1 | CK6: =MONTH(E6) -> 10 | CL6: =YEAR(E6) -> 2025
A7: 45667.497 | B7: sshinyc117@gmail.com | C7: 0 / 40 | D7: Shiny | E7: 45931 | F7: Wireless | G7: 9/30/2025 | H7: 9447997090 | I7: 156 | J7: SBM485 | K7: Malayalam | L7: Kerala | M7: No | N7: Yes | O7: Yes | P7: Yes | Q7: Yes | R7: No | S7: Yes | T7: Yes | U7: Yes | V7: Yes | W7: Yes | X7: Yes | Y7: Yes | Z7: Yes | AA7: No | AB7: Yes | AC7: No | AD7: Yes | AE7: Yes | AF7: Not Applicable | AG7: No | AH7: Not Applicable | AI7: Not Applicable | AJ7: Yes | AK7: Not Applicable | AL7: No | AM7: Yes | AN7: Yes | AO7: Yes | AP7: correct greeting not used, empathy missing, correct information not shared, dead air | AQ7: Customer having data connectivity issue. Advisor complete probing to customer as per call and given APN settings. | AR7: Prepaid | AS7: DATA SERVICES | AT7: UNABLE TO BROWSE DATA | AW7: =IF(OR(M7="YES", M7="Not Applicable"), AW$1, "0") -> 0 | AX7: =IF(OR(N7="YES", N7="Not Applicable"), AX$1, "0") -> 4 | AY7: =IF(OR(O7="YES", O7="Not Applicable"), AY$1, "0") -> 4 | AZ7: =IF(OR(P7="YES", P7="Not Applicable"), AZ$1, "0") -> 2 | BA7: =IF(OR(Q7="YES", Q7="Not Applicable"), BA$1, "0") -> 4 | BB7: =IF(OR(R7="YES", R7="Not Applicable"), BB$1, "0") -> 0 | BC7: =IF(OR(S7="YES", S7="Not Applicable"), BC$1, "0") -> 4 | BD7: =IF(OR(T7="YES", T7="Not Applicable"), BD$1, "0") -> 2 | ... BY7: =IF(OR(AO7="YES", AO7="Not Applicable"), BY$1, "0") -> 0 | BZ7: =SUM(AW7:BY7) -> 76 | CA7: =VLOOKUP(J:J,'Agent wise'!A:C,3,0) -> Saran S | CB7: =INT(E7) -> 45931 | CC7: =IF(BZ7>=94.5, "Excellent", IF(BZ7>89.5, "Good", IF(BZ7>84.5, "Average", "FC"))) -> FC | CJ7: =DAY(E7) -> 1 | CK7: =MONTH(E7) -> 10 | CL7: =YEAR(E7) -> 2025
A8: 45667.502 | B8: sshinyc117@gmail.com | C8: 0 / 40 | D8: Shiny | E8: 45931 | F8: Wireless | G8: 9/30/2025 | H8: 9445365382 | I8: 168 | J8: SBM692 | K8: English | L8: Tamil Nadu | M8: No | N8: Yes | O8: Yes | P8: Yes | Q8: Yes | R8: Yes | S8: Yes | T8: Yes | U8: Yes | V8: Yes | W8: Yes | X8: Yes | Y8: Yes | Z8: Yes | AA8: Yes | AB8: Yes | AC8: Not Applicable | AD8: Yes | AE8: Yes | AF8: Not Applicable | AG8: Yes | AH8: Not Applicable | AI8: Not Applicable | AJ8: Yes | AK8: Not Applicable | AL8: No | AM8: Yes | AN8: Yes | AO8: Yes | AP8: correct greeting not used | AQ8: Customer having 4G and volte related enquiry. Advisor complete probing to customer as per call and register request for volte activation , | AR8: Prepaid | AS8: DATA SERVICES | AT8: UNABLE TO BROWSE DATA | AW8: =IF(OR(M8="YES", M8="Not Applicable"), AW$1, "0") -> 0 | AX8: =IF(OR(N8="YES", N8="Not Applicable"), AX$1, "0") -> 4 | AY8: =IF(OR(O8="YES", O8="Not Applicable"), AY$1, "0") -> 4 | AZ8: =IF(OR(P8="YES", P8="Not Applicable"), AZ$1, "0") -> 2 | BA8: =IF(OR(Q8="YES", Q8="Not Applicable"), BA$1, "0") -> 4 | BB8: =IF(OR(R8="YES", R8="Not Applicable"), BB$1, "0") -> 4 | BC8: =IF(OR(S8="YES", S8="Not Applicable"), BC$1, "0") -> 4 | BD8: =IF(OR(T8="YES", T8="Not Applicable"), BD$1, "0") -> 2 | ... BY8: =IF(OR(AO8="YES", AO8="Not Applicable"), BY$1, "0") -> 0 | BZ8: =SUM(AW8:BY8) -> 94 | CA8: =VLOOKUP(J:J,'Agent wise'!A:C,3,0) -> Saran S | CB8: =INT(E8) -> 45931 | CC8: =IF(BZ8>=94.5, "Excellent", IF(BZ8>89.5, "Good", IF(BZ8>84.5, "Average", "FC"))) -> Good | CJ8: =DAY(E8) -> 1 | CK8: =MONTH(E8) -> 10 | CL8: =YEAR(E8) -> 2025
A9: 45667.541 | B9: sshinyc117@gmail.com | C9: 0 / 40 | D9: Shiny | E9: 45931 | F9: MNP OBD | G9: 9/30/2025 | H9: 9443178739 | I9: 211 | J9: SBM267 | K9: Tamil | L9: Tamil Nadu | M9: Yes | N9: Yes | O9: Yes | P9: Yes | Q9: Yes | R9: Yes | S9: Yes | T9: Yes | U9: Yes | V9: Yes | W9: Yes | X9: Yes | Y9: Yes | Z9: Yes | AA9: No | AB9: No | AC9: No | AD9: Yes | AE9: Yes | AF9: Not Applicable | AG9: Yes | AH9: Not Applicable | AI9: Not Applicable | AJ9: Yes | AK9: Not Applicable | AL9: No | AM9: Yes | AN9: Yes | AO9: Yes | AP9: empathy & apology missing, dead air | AQ9: Customer having network connectivity issue in Abroad . Advisor complete probing to customer as per call and collect information regarding port out , | AR9: Prepaid | AS9: COMPLETE CALL | AT9: NOT AGREED | AW9: =IF(OR(M9="YES", M9="Not Applicable"), AW$1, "0") -> 6 | AX9: =IF(OR(N9="YES", N9="Not Applicable"), AX$1, "0") -> 4 | AY9: =IF(OR(O9="YES", O9="Not Applicable"), AY$1, "0") -> 4 | AZ9: =IF(OR(P9="YES", P9="Not Applicable"), AZ$1, "0") -> 2 | BA9: =IF(OR(Q9="YES", Q9="Not Applicable"), BA$1, "0") -> 4 | BB9: =IF(OR(R9="YES", R9="Not Applicable"), BB$1, "0") -> 4 | BC9: =IF(OR(S9="YES", S9="Not Applicable"), BC$1, "0") -> 4 | BD9: =IF(OR(T9="YES", T9="Not Applicable"), BD$1, "0") -> 2 | ... BY9: =IF(OR(AO9="YES", AO9="Not Applicable"), BY$1, "0") -> 0 | BZ9: =SUM(AW9:BY9) -> 90 | CA9: =VLOOKUP(J:J,'Agent wise'!A:C,3,0) -> Saran S | CB9: =INT(E9) -> 45931 | CC9: =IF(BZ9>=94.5, "Excellent", IF(BZ9>89.5, "Good", IF(BZ9>84.5, "Average", "FC"))) -> Good | CJ9: =DAY(E9) -> 1 | CK9: =MONTH(E9) -> 10 | CL9: =YEAR(E9) -> 2025
A10: 45667.584 | B10: sshinyc117@gmail.com | C10: 0 / 40 | D10: Shiny | E10: 45931 | F10: MNP OBD | G10: 9/30/2025 | H10: 9698886964 | I10: 189 | J10: SBM744 | K10: Tamil | L10: Tamil Nadu | M10: Yes | N10: Yes | O10: Yes | P10: Yes | Q10: Yes | R10: Yes | S10: Yes | T10: Yes | U10: Yes | V10: Yes | W10: Yes | X10: Yes | Y10: Yes | Z10: Yes | AA10: No | AB10: No | AC10: Not Applicable | AD10: No | AE10: Yes | AF10: Not Applicable | AG10: Yes | AH10: Not Applicable | AI10: No | AJ10: Yes | AK10: Not Applicable | AL10: No | AM10: Yes | AN10: Yes | AO10: Yes | AP10: empathy & apology missing | AQ10: Customer having weak signal and data connectivity issue. Advisor complete probing to customer as per call and capture port out reason , | AR10: Prepaid | AS10: COMPLETE CALL | AT10: NOT AGREED | AW10: =IF(OR(M10="YES", M10="Not Applicable"), AW$1, "0") -> 6 | AX10: =IF(OR(N10="YES", N10="Not Applicable"), AX$1, "0") -> 4 | AY10: =IF(OR(O10="YES", O10="Not Applicable"), AY$1, "0") -> 4 | AZ10: =IF(OR(P10="YES", P10="Not Applicable"), AZ$1, "0") -> 2 | BA10: =IF(OR(Q10="YES", Q10="Not Applicable"), BA$1, "0") -> 4 | BB10: =IF(OR(R10="YES", R10="Not Applicable"), BB$1, "0") -> 4 | BC10: =IF(OR(S10="YES", S10="Not Applicable"), BC$1, "0") -> 4 | BD10: =IF(OR(T10="YES", T10="Not Applicable"), BD$1, "0") -> 2 | ... BY10: =IF(OR(AO10="YES", AO10="Not Applicable"), BY$1, "0") -> 0 | BZ10: =SUM(AW10:BY10) -> 86 | CA10: =VLOOKUP(J:J,'Agent wise'!A:C,3,0) -> Shiny | CB10: =INT(E10) -> 45931 | CC10: =IF(BZ10>=94.5, "Excellent", IF(BZ10>89.5, "Good", IF(BZ10>84.5, "Average", "FC"))) -> Average | CJ10: =DAY(E10) -> 1 | CK10: =MONTH(E10) -> 10 | CL10: =YEAR(E10) -> 2025
A11: 45667.732 | B11: priyankajino2013@gmail.com | C11: 0 / 40 | D11: Priyanka | E11: 45931 | F11: Wireless | G11: 9/30/2025 | H11: 8078889156 | I11: 197 | J11: VPS259 | K11: Malayalam | L11: Kerala | M11: Yes | N11: Yes | O11: Yes | P11: Yes | Q11: Yes | R11: No | S11: Yes | T11: Yes | U11: No | V11: Yes | W11: Yes | X11: Yes | Y11: Yes | Z11: Yes | AA11: No | AB11: No | AC11: No | AD11: Yes | AE11: No | AF11: Not Applicable | AG11: No | AH11: Yes | AI11: Not Applicable | AJ11: Yes | AK11: Yes | AL11: No | AM11: Yes | AN11: Yes | AO11: No | AP11: AOI-dead air,empathy missing,aplology missing | AQ11: Opening & Introduction â€“ Done Customer details captured â€“Done Customer concern -Customer ask network issue Resolution shared - Advisor complete probing to customers as per call setting provide Closing as per standard - Done. AOI-dead air,empathy missing,aplology missing | AR11: Prepaid | AS11: DATA SERVICES | AT11: DATA DEACTIVATION | AW11: =IF(OR(M11="YES", M11="Not Applicable"), AW$1, "0") -> 6 | AX11: =IF(OR(N11="YES", N11="Not Applicable"), AX$1, "0") -> 4 | AY11: =IF(OR(O11="YES", O11="Not Applicable"), AY$1, "0") -> 4 | AZ11: =IF(OR(P11="YES", P11="Not Applicable"), AZ$1, "0") -> 2 | BA11: =IF(OR(Q11="YES", Q11="Not Applicable"), BA$1, "0") -> 4 | BB11: =IF(OR(R11="YES", R11="Not Applicable"), BB$1, "0") -> 0 | BC11: =IF(OR(S11="YES", S11="Not Applicable"), BC$1, "0") -> 4 | BD11: =IF(OR(T11="YES", T11="Not Applicable"), BD$1, "0") -> 2 | ... BY11: =IF(OR(AO11="YES", AO11="Not Applicable"), BY$1, "0") -> 0 | BZ11: =SUM(AW11:BY11) -> 72 | CA11: =VLOOKUP(J:J,'Agent wise'!A:C,3,0) -> Shakeer | CB11: =INT(E11) -> 45931 | CC11: =IF(BZ11>=94.5, "Excellent", IF(BZ11>89.5, "Good", IF(BZ11>84.5, "Average", "FC"))) -> FC | CJ11: =DAY(E11) -> 1 | CK11: =MONTH(E11) -> 10 | CL11: =YEAR(E11) -> 2025
A12: 45667.933 | B12: shakeerfazal11@gmail.com | C12: 0 / 40 | D12: Shakeer | E12: 45931 | F12: Wireless | G12: 45667 | H12: 9443654944 | I12: 145 | J12: VPS111 | K12: Tamil | L12: Tamil Nadu | M12: Yes | N12: Yes | O12: No | P12: Yes | Q12: Yes | R12: Yes | S12: Yes | T12: Yes | U12: No | V12: Yes | W12: Yes | X12: Not Applicable | Y12: Yes | Z12: Yes | AA12: No | AB12: No | AC12: Not Applicable | AD12: Yes | AE12: Yes | AF12: Not Applicable | AG12: Yes | AH12: Not Applicable | AI12: Not Applicable | AJ12: Yes | AK12: Yes | AL12: No | AM12: Yes | AN12: Yes | AO12: Yes | AP12: Not asked customer name, Not used empathy and apology words, No further assistance | AQ12: Customer called and inquired about Validity and plans related issue, Agent checked and given validity and plans details correctly. but not followed required quality parameter properly. | AR12: Prepaid | AS12: PLANS AND VALIDITY DETAILS | AT12: ENQUIRY ON BALANCE AND VALIDITY | AW12: =IF(OR(M12="YES", M12="Not Applicable"), AW$1, "0") -> 6 | AX12: =IF(OR(N12="YES", N12="Not Applicable"), AX$1, "0") -> 4 | AY12: =IF(OR(O12="YES", O12="Not Applicable"), AY$1, "0") -> 0 | AZ12: =IF(OR(P12="YES", P12="Not Applicable"), AZ$1, "0") -> 2 | BA12: =IF(OR(Q12="YES", Q12="Not Applicable"), BA$1, "0") -> 4 | BB12: =IF(OR(R12="YES", R12="Not Applicable"), BB$1, "0") -> 4 | BC12: =IF(OR(S12="YES", S12="Not Applicable"), BC$1, "0") -> 4 | BD12: =IF(OR(T12="YES", T12="Not Applicable"), BD$1, "0") -> 2 | ... BY12: =IF(OR(AO12="YES", AO12="Not Applicable"), BY$1, "0") -> 0 | BZ12: =SUM(AW12:BY12) -> 86 | CA12: =VLOOKUP(J:J,'Agent wise'!A:C,3,0) -> Shiny | CB12: =INT(E12) -> 45931 | CC12: =IF(BZ12>=94.5, "Excellent", IF(BZ12>89.5, "Good", IF(BZ12>84.5, "Average", "FC"))) -> Average | CJ12: =DAY(E12) -> 1 | CK12: =MONTH(E12) -> 10 | CL12: =YEAR(E12) -> 2025
A13: 45667.935 | B13: shakeerfazal11@gmail.com | C13: 0 / 40 | D13: Shakeer | E13: 45931 | F13: Wireless | G13: 45667 | H13: 7550281435 | I13: 145 | J13: VPS111 | K13: Tamil | L13: Tamil Nadu | M13: Yes | N13: Yes | O13: Yes | P13: Yes | Q13: Yes | R13: Yes | S13: Yes | T13: Yes | U13: No | V13: Yes | W13: Yes | X13: Not Applicable | Y13: Yes | Z13: No | AA13: No | AB13: No | AC13: Not Applicable | AD13: Not Applicable | AE13: Yes | AF13: Not Applicable | AG13: Yes | AH13: Not Applicable | AI13: Not Applicable | AJ13: Yes | AK13: Yes | AL13: No | AM13: Yes | AN13: Yes | AO13: Yes | AP13: No active listening skill, Not used empathy and apology words, No further assistance | AQ13: Customer called and inquired about PUK related issue, Agent checked and given proper information but not followed required quality parameter properly. | AR13: Prepaid | AS13: BSNL SELF CARE SERVICES | AT13: PUK CODE | AW13: =IF(OR(M13="YES", M13="Not Applicable"), AW$1, "0") -> 6 | AX13: =IF(OR(N13="YES", N13="Not Applicable"), AX$1, "0") -> 4 | AY13: =IF(OR(O13="YES", O13="Not Applicable"), AY$1, "0") -> 4 | AZ13: =IF(OR(P13="YES", P13="Not Applicable"), AZ$1, "0") -> 2 | BA13: =IF(OR(Q13="YES", Q13="Not Applicable"), BA$1, "0") -> 4 | BB13: =IF(OR(R13="YES", R13="Not Applicable"), BB$1, "0") -> 4 | BC13: =IF(OR(S13="YES", S13="Not Applicable"), BC$1, "0") -> 4 | BD13: =IF(OR(T13="YES", T13="Not Applicable"), BD$1, "0") -> 2 | ... BY13: =IF(OR(AO13="YES", AO13="Not Applicable"), BY$1, "0") -> 0 | BZ13: =SUM(AW13:BY13) -> 88 | CA13: =VLOOKUP(J:J,'Agent wise'!A:C,3,0) -> Shiny | CB13: =INT(E13) -> 45931 | CC13: =IF(BZ13>=94.5, "Excellent", IF(BZ13>89.5, "Good", IF(BZ13>84.5, "Average", "FC"))) -> Average | CJ13: =DAY(E13) -> 1 | CK13: =MONTH(E13) -> 10 | CL13: =YEAR(E13) -> 2025
A14: 45667.941 | B14: shakeerfazal11@gmail.com | C14: 0 / 40 | D14: Shakeer | E14: 45931 | F14: Wireless | G14: 45667 | H14: 9495225276 | I14: 155 | J14: VPS184 | K14: Malayalam | L14: Kerala | M14: Yes | N14: Yes | O14: Yes | P14: Yes | Q14: Yes | R14: Yes | S14: Yes | T14: Yes | U14: No | V14: Yes | W14: Yes | X14: Not Applicable | Y14: Yes | Z14: Yes | AA14: No | AB14: No | AC14: No | AD14: Not Applicable | AE14: Yes | AF14: Not Applicable | AG14: Yes | AH14: Not Applicable | AI14: Not Applicable | AJ14: Yes | AK14: Yes | AL14: No | AM14: Yes | AN14: Yes | AO14: Yes | AP14: Not used empathy and apology words, Dead air, No further assistance | AQ14: Customer called and inquired about Validity related issue, Agent checked and given Validity details, but not followed required quality parameter properly. | AR14: Prepaid | AS14: PLANS AND VALIDITY DETAILS | AT14: ENQUIRY ON BALANCE AND VALIDITY | AW14: =IF(OR(M14="YES", M14="Not Applicable"), AW$1, "0") -> 6 | AX14: =IF(OR(N14="YES", N14="Not Applicable"), AX$1, "0") -> 4 | AY14: =IF(OR(O14="YES", O14="Not Applicable"), AY$1, "0") -> 4 | AZ14: =IF(OR(P14="YES", P14="Not Applicable"), AZ$1, "0") -> 2 | BA14: =IF(OR(Q14="YES", Q14="Not Applicable"), BA$1, "0") -> 4 | BB14: =IF(OR(R14="YES", R14="Not Applicable"), BB$1, "0") -> 4 | BC14: =IF(OR(S14="YES", S14="Not Applicable"), BC$1, "0") -> 4 | BD14: =IF(OR(T14="YES", T14="Not Applicable"), BD$1, "0") -> 2 | ... BY14: =IF(OR(AO14="YES", AO14="Not Applicable"), BY$1, "0") -> 0 | BZ14: =SUM(AW14:BY14) -> 86 | CA14: =VLOOKUP(J:J,'Agent wise'!A:C,3,0) -> Saran S | CB14: =INT(E14) -> 45931 | CC14: =IF(BZ14>=94.5, "Excellent", IF(BZ14>89.5, "Good", IF(BZ14>84.5, "Average", "FC"))) -> Average | CJ14: =DAY(E14) -> 1 | CK14: =MONTH(E14) -> 10 | CL14: =YEAR(E14) -> 2025
A15: 45667.948 | B15: shakeerfazal11@gmail.com | C15: 0 / 40 | D15: Shakeer | E15: 45931 | F15: Wireless | G15: 45667 | H15: 9496541608 | I15: 161 | J15: VPS184 | K15: Malayalam | L15: Kerala | M15: Yes | N15: Yes | O15: Yes | P15: Yes | Q15: Yes | R15: Yes | S15: Yes | T15: Yes | U15: No | V15: Yes | W15: Yes | X15: Not Applicable | Y15: Yes | Z15: Yes | AA15: No | AB15: No | AC15: No | AD15: Not Applicable | AE15: Yes | AF15: Not Applicable | AG15: Yes | AH15: Not Applicable | AI15: Yes | AJ15: Yes | AK15: Yes | AL15: No | AM15: Yes | AN15: Yes | AO15: Yes | AP15: Not used empathy and apology words, Dead air, No further assistance | AQ15: Customer called and inquired about Weak signal related issue, Agent checked and taken poor coverage related complaint. But not followed required quality parameter properly | AR15: Prepaid | AS15: COMPLAINT | AT15: POOR NETWORK COVERAGE | AW15: =IF(OR(M15="YES", M15="Not Applicable"), AW$1, "0") -> 6 | AX15: =IF(OR(N15="YES", N15="Not Applicable"), AX$1, "0") -> 4 | AY15: =IF(OR(O15="YES", O15="Not Applicable"), AY$1, "0") -> 4 | AZ15: =IF(OR(P15="YES", P15="Not Applicable"), AZ$1, "0") -> 2 | BA15: =IF(OR(Q15="YES", Q15="Not Applicable"), BA$1, "0") -> 4 | BB15: =IF(OR(R15="YES", R15="Not Applicable"), BB$1, "0") -> 4 | BC15: =IF(OR(S15="YES", S15="Not Applicable"), BC$1, "0") -> 4 | BD15: =IF(OR(T15="YES", T15="Not Applicable"), BD$1, "0") -> 2 | ... BY15: =IF(OR(AO15="YES", AO15="Not Applicable"), BY$1, "0") -> 0 | BZ15: =SUM(AW15:BY15) -> 86 | CA15: =VLOOKUP(J:J,'Agent wise'!A:C,3,0) -> Saran S | CB15: =INT(E15) -> 45931 | CC15: =IF(BZ15>=94.5, "Excellent", IF(BZ15>89.5, "Good", IF(BZ15>84.5, "Average", "FC"))) -> Average | CJ15: =DAY(E15) -> 1 | CK15: =MONTH(E15) -> 10 | CL15: =YEAR(E15) -> 2025
A16: 45667.95 | B16: shakeerfazal11@gmail.com | C16: 0 / 40 | D16: Shakeer | E16: 45931 | F16: Wireless | G16: 45667 | H16: 8122448625 | I16: 148 | J16: SBM958 | K16: Tamil | L16: Tamil Nadu | M16: Yes | N16: Yes | O16: Yes | P16: Yes | Q16: Yes | R16: Yes | S16: Yes | T16: Yes | U16: No | V16: Yes | W16: Yes | X16: Not Applicable | Y16: Yes | Z16: Yes | AA16: No | AB16: No | AC16: Not Applicable | AD16: Yes | AE16: Yes | AF16: Not Applicable | AG16: Yes | AH16: Not Applicable | AI16: Not Applicable | AJ16: Yes | AK16: Yes | AL16: No | AM16: Yes | AN16: Yes | AO16: Yes | AP16: Not used empathy and apology words, No further assistance | AQ16: Customer called and inquired about Sim Lost related issue, Agent checked and given taken SIM block request properly. But not followed required quality parameter properly. | AR16: Prepaid | AS16: SIM BLOCK | AT16: SIM BLOCKDUE TO SIM LOST | AW16: =IF(OR(M16="YES", M16="Not Applicable"), AW$1, "0") -> 6 | AX16: =IF(OR(N16="YES", N16="Not Applicable"), AX$1, "0") -> 4 | AY16: =IF(OR(O16="YES", O16="Not Applicable"), AY$1, "0") -> 4 | AZ16: =IF(OR(P16="YES", P16="Not Applicable"), AZ$1, "0") -> 2 | BA16: =IF(OR(Q16="YES", Q16="Not Applicable"), BA$1, "0") -> 4 | BB16: =IF(OR(R16="YES", R16="Not Applicable"), BB$1, "0") -> 4 | BC16: =IF(OR(S16="YES", S16="Not Applicable"), BC$1, "0") -> 4 | BD16: =IF(OR(T16="YES", T16="Not Applicable"), BD$1, "0") -> 2 | ... BY16: =IF(OR(AO16="YES", AO16="Not Applicable"), BY$1, "0") -> 0 | BZ16: =SUM(AW16:BY16) -> 90 | CA16: =VLOOKUP(J:J,'Agent wise'!A:C,3,0) -> Saran S | CB16: =INT(E16) -> 45931 | CC16: =IF(BZ16>=94.5, "Excellent", IF(BZ16>89.5, "Good", IF(BZ16>84.5, "Average", "FC"))) -> Good | CJ16: =DAY(E16) -> 1 | CK16: =MONTH(E16) -> 10 | CL16: =YEAR(E16) -> 2025
A17: 45667.955 | B17: shakeerfazal11@gmail.com | C17: 0 / 40 | D17: Shakeer | E17: 45931 | F17: Wireless | G17: 45667 | H17: 9965913212 | I17: 153 | J17: SBM958 | K17: Tamil | L17: Tamil Nadu | M17: No | N17: Yes | O17: Yes | P17: Yes | Q17: Yes | R17: Yes | S17: Yes | T17: Yes | U17: No | V17: Yes | W17: Yes | X17: Not Applicable | Y17: Yes | Z17: Yes | AA17: No | AB17: No | AC17: No | AD17: Yes | AE17: Yes | AF17: Not Applicable | AG17: Yes | AH17: Not Applicable | AI17: Not Applicable | AJ17: Yes | AK17: Yes | AL17: No | AM17: Yes | AN17: Yes | AO17: Yes | AP17: Not used empathy and apology words, Dead air, No further assistance | AQ17: Customer called and inquired about Validity related issue, Agent checked and given Validity details. but not followed required quality parameter properly. | AR17: Prepaid | AS17: PLANS AND VALIDITY DETAILS | AT17: ENQUIRY ON BALANCE AND VALIDITY | AW17: =IF(OR(M17="YES", M17="Not Applicable"), AW$1, "0") -> 0 | AX17: =IF(OR(N17="YES", N17="Not Applicable"), AX$1, "0") -> 4 | AY17: =IF(OR(O17="YES", O17="Not Applicable"), AY$1, "0") -> 4 | AZ17: =IF(OR(P17="YES", P17="Not Applicable"), AZ$1, "0") -> 2 | BA17: =IF(OR(Q17="YES", Q17="Not Applicable"), BA$1, "0") -> 4 | BB17: =IF(OR(R17="YES", R17="Not Applicable"), BB$1, "0") -> 4 | BC17: =IF(OR(S17="YES", S17="Not Applicable"), BC$1, "0") -> 4 | BD17: =IF(OR(T17="YES", T17="Not Applicable"), BD$1, "0") -> 2 | ... BY17: =IF(OR(AO17="YES", AO17="Not Applicable"), BY$1, "0") -> 0 | BZ17: =SUM(AW17:BY17) -> 80 | CA17: =VLOOKUP(J:J,'Agent wise'!A:C,3,0) -> Saran S | CB17: =INT(E17) -> 45931 | CC17: =IF(BZ17>=94.5, "Excellent", IF(BZ17>89.5, "Good", IF(BZ17>84.5, "Average", "FC"))) -> FC | CJ17: =DAY(E17) -> 1 | CK17: =MONTH(E17) -> 10 | CL17: =YEAR(E17) -> 2025
A18: 45667.956 | B18: saranchirayinkeezhu720@gmail.com | C18: 0 / 40 | D18: Saran | E18: 45931 | F18: Wireless | G18: 45667 | H18: 8086771246 | I18: 128 | J18: SBM314 | K18: Malayalam | L18: Kerala | M18: No | N18: Yes | O18: Yes | P18: Yes | Q18: Yes | R18: Yes | S18: Yes | T18: Yes | U18: No | V18: Yes | W18: Yes | X18: Yes | Y18: Yes | Z18: Yes | AA18: Yes | AB18: Yes | AC18: Yes | AD18: Yes | AE18: Yes | AF18: Not Applicable | AG18: No | AH18: Not Applicable | AI18: Not Applicable | AJ18: Yes | AK18: Yes | AL18: Yes | AM18: Yes | AN18: Yes | AO18: Yes | AP18: Not given accurate information | AQ18: Customer concern -Customer called for unable to get sms . Resolution shared - Advisor done complete probing to customer as per call. | AR18: Prepaid | AS18: SMS SERVICES | AT18: UNABLE TO RECEIVE SMS | AW18: =IF(OR(M18="YES", M18="Not Applicable"), AW$1, "0") -> 0 | AX18: =IF(OR(N18="YES", N18="Not Applicable"), AX$1, "0") -> 4 | AY18: =IF(OR(O18="YES", O18="Not Applicable"), AY$1, "0") -> 4 | AZ18: =IF(OR(P18="YES", P18="Not Applicable"), AZ$1, "0") -> 2 | BA18: =IF(OR(Q18="YES", Q18="Not Applicable"), BA$1, "0") -> 4 | BB18: =IF(OR(R18="YES", R18="Not Applicable"), BB$1, "0") -> 4 | BC18: =IF(OR(S18="YES", S18="Not Applicable"), BC$1, "0") -> 4 | BD18: =IF(OR(T18="YES", T18="Not Applicable"), BD$1, "0") -> 2 | ... BY18: =IF(OR(AO18="YES", AO18="Not Applicable"), BY$1, "0") -> 0 | BZ18: =SUM(AW18:BY18) -> 84 | CA18: =VLOOKUP(J:J,'Agent wise'!A:C,3,0) -> Shakeer | CB18: =INT(E18) -> 45931 | CC18: =IF(BZ18>=94.5, "Excellent", IF(BZ18>89.5, "Good", IF(BZ18>84.5, "Average", "FC"))) -> FC | CJ18: =DAY(E18) -> 1 | CK18: =MONTH(E18) -> 10 | CL18: =YEAR(E18) -> 2025
A19: 45667.959 | B19: shakeerfazal11@gmail.com | C19: 0 / 40 | D19: Shakeer | E19: 45931 | F19: Wireless | G19: 45667 | H19: 9965913212 | I19: 153 | J19: SBM958 | K19: Tamil | L19: Tamil Nadu | M19: No | N19: Yes | O19: Yes | P19: Yes | Q19: Yes | R19: Yes | S19: Yes | T19: Yes | U19: No | V19: Yes | W19: Yes | X19: Not Applicable | Y19: Yes | Z19: Yes | AA19: No | AB19: No | AC19: No | AD19: Not Applicable | AE19: Yes | AF19: Not Applicable | AG19: Yes | AH19: Not Applicable | AI19: Not Applicable | AJ19: Yes | AK19: Yes | AL19: No | AM19: Yes | AN19: Yes | AO19: Yes | AP19: Not used empathy and apology words, Dead air, Delay opening the call, No further assistance | AQ19: Customer called and inquired about Validity related issue, Agent checked and given SIM validity details. but not followed required quality parameter properly. | AR19: Prepaid | AS19: PLANS AND VALIDITY DETAILS | AT19: ENQUIRY ON BALANCE AND VALIDITY | AW19: =IF(OR(M19="YES", M19="Not Applicable"), AW$1, "0") -> 0 | AX19: =IF(OR(N19="YES", N19="Not Applicable"), AX$1, "0") -> 4 | AY19: =IF(OR(O19="YES", O19="Not Applicable"), AY$1, "0") -> 4 | AZ19: =IF(OR(P19="YES", P19="Not Applicable"), AZ$1, "0") -> 2 | BA19: =IF(OR(Q19="YES", Q19="Not Applicable"), BA$1, "0") -> 4 | BB19: =IF(OR(R19="YES", R19="Not Applicable"), BB$1, "0") -> 4 | BC19: =IF(OR(S19="YES", S19="Not Applicable"), BC$1, "0") -> 4 | BD19: =IF(OR(T19="YES", T19="Not Applicable"), BD$1, "0") -> 2 | ... BY19: =IF(OR(AO19="YES", AO19="Not Applicable"), BY$1, "0") -> 0 | BZ19: =SUM(AW19:BY19) -> 80 | CA19: =VLOOKUP(J:J,'Agent wise'!A:C,3,0) -> Saran S | CB19: =INT(E19) -> 45931 | CC19: =IF(BZ19>=94.5, "Excellent", IF(BZ19>89.5, "Good", IF(BZ19>84.5, "Average", "FC"))) -> FC | CJ19: =DAY(E19) -> 1 | CK19: =MONTH(E19) -> 10 | CL19: =YEAR(E19) -> 2025
A20: 45667.96 | B20: saranchirayinkeezhu720@gmail.com | C20: 0 / 40 | D20: Saran | E20: 45931 | F20: Wireless | G20: 45667 | H20: 9884511639 | I20: 128 | J20: SBM550 | K20: Tamil | L20: Tamil Nadu | M20: Yes | N20: Yes | O20: Yes | P20: Yes | Q20: Yes | R20: Yes | S20: Yes | T20: Yes | U20: No | V20: Yes | W20: Yes | X20: Yes | Y20: Yes | Z20: Yes | AA20: Yes | AB20: No | AC20: Yes | AD20: Yes | AE20: Yes | AF20: Not Applicable | AG20: Yes | AH20: Not Applicable | AI20: No | AJ20: Yes | AK20: Yes | AL20: No | AM20: Yes | AN20: Yes | AO20: Yes | AP20: Not taken complaint for customer, No apology | AQ20: Customer concern -Customer called for network issue . Resolution shared - Advisor done complete probing to customer as per call. | AR20: Prepaid | AS20: VOICE SERVICES | AT20: WRONG ROUTING OF CALL | AW20: =IF(OR(M20="YES", M20="Not Applicable"), AW$1, "0") -> 6 | AX20: =IF(OR(N20="YES", N20="Not Applicable"), AX$1, "0") -> 4 | AY20: =IF(OR(O20="YES", O20="Not Applicable"), AY$1, "0") -> 4 | AZ20: =IF(OR(P20="YES", P20="Not Applicable"), AZ$1, "0") -> 2 | BA20: =IF(OR(Q20="YES", Q20="Not Applicable"), BA$1, "0") -> 4 | BB20: =IF(OR(R20="YES", R20="Not Applicable"), BB$1, "0") -> 4 | BC20: =IF(OR(S20="YES", S20="Not Applicable"), BC$1, "0") -> 4 | BD20: =IF(OR(T20="YES", T20="Not Applicable"), BD$1, "0") -> 2 | ... BY20: =IF(OR(AO20="YES", AO20="Not Applicable"), BY$1, "0") -> 0 | BZ20: =SUM(AW20:BY20) -> 90 | CA20: =VLOOKUP(J:J,'Agent wise'!A:C,3,0) -> Shakeer | CB20: =INT(E20) -> 45931 | CC20: =IF(BZ20>=94.5, "Excellent", IF(BZ20>89.5, "Good", IF(BZ20>84.5, "Average", "FC"))) -> Good | CJ20: =DAY(E20) -> 1 | CK20: =MONTH(E20) -> 10 | CL20: =YEAR(E20) -> 2025
A21: 45667.961 | B21: shakeerfazal11@gmail.com | C21: 0 / 40 | D21: Shakeer | E21: 45931 | F21: Wireless | G21: 45667 | H21: 9745718491 | I21: 199 | J21: SBM724 | K21: Malayalam | L21: Kerala | M21: Yes | N21: Yes | O21: Yes | P21: Yes | Q21: Yes | R21: Yes | S21: Yes | T21: Yes | U21: No | V21: Yes | W21: Yes | X21: Not Applicable | Y21: Yes | Z21: Yes | AA21: Yes | AB21: Yes | AC21: No | AD21: Yes | AE21: Yes | AF21: Not Applicable | AG21: Yes | AH21: Not Applicable | AI21: Yes | AJ21: Yes | AK21: Yes | AL21: No | AM21: Yes | AN21: Yes | AO21: Yes | AP21: Dead air, No further assistance | AQ21: Customer called and inquired about Weak signal related issue, Agent checked and taken poor coverage related complaint. but not followed required quality parameter properly. | AR21: Prepaid | AS21: COMPLAINT | AT21: POOR NETWORK COVERAGE | AW21: =IF(OR(M21="YES", M21="Not Applicable"), AW$1, "0") -> 6 | AX21: =IF(OR(N21="YES", N21="Not Applicable"), AX$1, "0") -> 4 | AY21: =IF(OR(O21="YES", O21="Not Applicable"), AY$1, "0") -> 4 | AZ21: =IF(OR(P21="YES", P21="Not Applicable"), AZ$1, "0") -> 2 | BA21: =IF(OR(Q21="YES", Q21="Not Applicable"), BA$1, "0") -> 4 | BB21: =IF(OR(R21="YES", R21="Not Applicable"), BB$1, "0") -> 4 | BC21: =IF(OR(S21="YES", S21="Not Applicable"), BC$1, "0") -> 4 | BD21: =IF(OR(T21="YES", T21="Not Applicable"), BD$1, "0") -> 2 | ... BY21: =IF(OR(AO21="YES", AO21="Not Applicable"), BY$1, "0") -> 0 | BZ21: =SUM(AW21:BY21) -> 92 | CA21: =VLOOKUP(J:J,'Agent wise'!A:C,3,0) -> Shiny | CB21: =INT(E21) -> 45931 | CC21: =IF(BZ21>=94.5, "Excellent", IF(BZ21>89.5, "Good", IF(BZ21>84.5, "Average", "FC"))) -> Good | CJ21: =DAY(E21) -> 1 | CK21: =MONTH(E21) -> 10 | CL21: =YEAR(E21) -> 2025
A22: 45667.964 | B22: shakeerfazal11@gmail.com | C22: 0 / 40 | D22: Shakeer | E22: 45931 | F22: Wireless | G22: 45667 | H22: 9446148925 | I22: 141 | J22: SBM724 | K22: Malayalam | L22: Kerala | M22: Yes | N22: Yes | O22: Yes | P22: Yes | Q22: Yes | R22: Yes | S22: Yes | T22: Yes | U22: No | V22: Yes | W22: Yes | X22: Not Applicable | Y22: Yes | Z22: Yes | AA22: Yes | AB22: Yes | AC22: No | AD22: Not Applicable | AE22: Yes | AF22: Not Applicable | AG22: Yes | AH22: Not Applicable | AI22: Yes | AJ22: Yes | AK22: Yes | AL22: No | AM22: Yes | AN22: Yes | AO22: Yes | AP22: No further assistance, Dead air observed | AQ22: Customer called and inquired about Weak signal related issue, Agent checked and taken poor coverage related complaint. But not followed required quality parameter properly. | AR22: Prepaid | AS22: COMPLAINT | AT22: POOR NETWORK COVERAGE | AW22: =IF(OR(M22="YES", M22="Not Applicable"), AW$1, "0") -> 6 | AX22: =IF(OR(N22="YES", N22="Not Applicable"), AX$1, "0") -> 4 | AY22: =IF(OR(O22="YES", O22="Not Applicable"), AY$1, "0") -> 4 | AZ22: =IF(OR(P22="YES", P22="Not Applicable"), AZ$1, "0") -> 2 | BA22: =IF(OR(Q22="YES", Q22="Not Applicable"), BA$1, "0") -> 4 | BB22: =IF(OR(R22="YES", R22="Not Applicable"), BB$1, "0") -> 4 | BC22: =IF(OR(S22="YES", S22="Not Applicable"), BC$1, "0") -> 4 | BD22: =IF(OR(T22="YES", T22="Not Applicable"), BD$1, "0") -> 2 | ... BY22: =IF(OR(AO22="YES", AO22="Not Applicable"), BY$1, "0") -> 0 | BZ22: =SUM(AW22:BY22) -> 92 | CA22: =VLOOKUP(J:J,'Agent wise'!A:C,3,0) -> Shiny | CB22: =INT(E22) -> 45931 | CC22: =IF(BZ22>=94.5, "Excellent", IF(BZ22>89.5, "Good", IF(BZ22>84.5, "Average", "FC"))) -> Good | CJ22: =DAY(E22) -> 1 | CK22: =MONTH(E22) -> 10 | CL22: =YEAR(E22) -> 2025
A23: 45667.965 | B23: saranchirayinkeezhu720@gmail.com | C23: 0 / 40 | D23: Saran | E23: 45931 | F23: Wireless | G23: 45667 | H23: 8547100648 | I23: 160 | J23: SBM963 | K23: Malayalam | L23: Kerala | M23: Yes | N23: Yes | O23: Yes | P23: Yes | Q23: Yes | R23: Yes | S23: Yes | T23: Yes | U23: No | V23: Yes | W23: Yes | X23: Yes | Y23: Yes | Z23: Yes | AA23: Yes | AB23: Not Applicable | AC23: Not Applicable | AD23: Yes | AE23: Yes | AF23: Not Applicable | AG23: Yes | AH23: Not Applicable | AI23: Not Applicable | AJ23: Yes | AK23: Yes | AL23: No | AM23: Yes | AN23: Yes | AO23: Yes | AP23: No further assistance | AQ23: Customer concern -Customer called for wrong recharge issue. Resolution shared - Advisor done complete probing to customer as per call. | AR23: Prepaid | AS23: RECHARGE ISSUE | AT23: WRONG RECHARGE | AW23: =IF(OR(M23="YES", M23="Not Applicable"), AW$1, "0") -> 6 | AX23: =IF(OR(N23="YES", N23="Not Applicable"), AX$1, "0") -> 4 | AY23: =IF(OR(O23="YES", O23="Not Applicable"), AY$1, "0") -> 4 | AZ23: =IF(OR(P23="YES", P23="Not Applicable"), AZ$1, "0") -> 2 | BA23: =IF(OR(Q23="YES", Q23="Not Applicable"), BA$1, "0") -> 4 | BB23: =IF(OR(R23="YES", R23="Not Applicable"), BB$1, "0") -> 4 | BC23: =IF(OR(S23="YES", S23="Not Applicable"), BC$1, "0") -> 4 | BD23: =IF(OR(T23="YES", T23="Not Applicable"), BD$1, "0") -> 2 | ... BY23: =IF(OR(AO23="YES", AO23="Not Applicable"), BY$1, "0") -> 0 | BZ23: =SUM(AW23:BY23) -> 96 | CA23: =VLOOKUP(J:J,'Agent wise'!A:C,3,0) -> Shakeer | CB23: =INT(E23) -> 45931 | CC23: =IF(BZ23>=94.5, "Excellent", IF(BZ23>89.5, "Good", IF(BZ23>84.5, "Average", "FC"))) -> Excellent | CJ23: =DAY(E23) -> 1 | CK23: =MONTH(E23) -> 10 | CL23: =YEAR(E23) -> 2025
... A28: 45698.006 | B28: saranchirayinkeezhu720@gmail.com | C28: 0 / 40 | D28: Saran | E28: 45931 | F28: Wireless | G28: 45667 | H28: 7845308011 | I28: 128 | J28: VPS229 | K28: Tamil | L28: Tamil Nadu | M28: Yes | N28: Yes | O28: Yes | P28: Yes | Q28: Yes | R28: Yes | S28: Yes | T28: Yes | U28: No | V28: Yes | W28: Yes | X28: Yes | Y28: Yes | Z28: Yes | AA28: No | AB28: No | AC28: No | AD28: Yes | AE28: Yes | AF28: Not Applicable | AG28: Yes | AH28: Not Applicable | AI28: Not Applicable | AJ28: Yes | AK28: Yes | AL28: No | AM28: Yes | AN28: Yes | AO28: Yes | AP28: Not use empathy and apology, Dead air. | AQ28: Customer concern -Customer called for not getting incoming calls . Resolution shared - Advisor done complete probing to customer as per call. | AR28: Prepaid | AS28: CALL SERVICES | AT28: RECHARGE PLAN NOT AVAILABLE | AW28: =IF(OR(M28="YES", M28="Not Applicable"), AW$1, "0") -> 6 | AX28: =IF(OR(N28="YES", N28="Not Applicable"), AX$1, "0") -> 4 | AY28: =IF(OR(O28="YES", O28="Not Applicable"), AY$1, "0") -> 4 | AZ28: =IF(OR(P28="YES", P28="Not Applicable"), AZ$1, "0") -> 2 | BA28: =IF(OR(Q28="YES", Q28="Not Applicable"), BA$1, "0") -> 4 | BB28: =IF(OR(R28="YES", R28="Not Applicable"), BB$1, "0") -> 4 | BC28: =IF(OR(S28="YES", S28="Not Applicable"), BC$1, "0") -> 4 | BD28: =IF(OR(T28="YES", T28="Not Applicable"), BD$1, "0") -> 2 | ... BY28: =IF(OR(AO28="YES", AO28="Not Applicable"), BY$1, "0") -> 0 | BZ28: =SUM(AW28:BY28) -> 86 | CA28: =VLOOKUP(J:J,'Agent wise'!A:C,3,0) -> Shakeer | CB28: =INT(E28) -> 45931 | CC28: =IF(BZ28>=94.5, "Excellent", IF(BZ28>89.5, "Good", IF(BZ28>84.5, "Average", "FC"))) -> Average | CJ28: =DAY(E28) -> 1 | CK28: =MONTH(E28) -> 10 | CL28: =YEAR(E28) -> 2025
A29: 45698.427 | B29: adharshleewvan003@gmail.com | C29: 0 / 40 | D29: Adharsh | E29: 45931 | F29: MNP OBD | G29: 9/30/2025 | H29: 9751204478 | I29: 181 | J29: SBM792 | K29: Tamil | L29: Tamil Nadu | M29: Yes | N29: Yes | O29: Yes | P29: Yes | Q29: Yes | R29: Yes | S29: Yes | T29: Yes | U29: Yes | V29: Yes | W29: Yes | X29: Yes | Y29: Yes | Z29: Yes | AA29: Yes | AB29: Yes | AC29: Not Applicable | AD29: Yes | AE29: No | AF29: Yes | AG29: Yes | AH29: Not Applicable | AI29: Not Applicable | AJ29: Yes | AK29: Yes | AL29: Yes | AM29: Yes | AN29: Yes | AO29: Yes | AP29: Maintained focus on caller's problem | AQ29: Reason for PORTING request: Has two SIM CARD in BSNL, so customer porting out to other network Resolution provided: Didn't completely Convinced customer to keep both the SIM in BSNL | AR29: Prepaid | AS29: QUERY | AT29: NOT AGREED | AW29: =IF(OR(M29="YES", M29="Not Applicable"), AW$1, "0") -> 6 | AX29: =IF(OR(N29="YES", N29="Not Applicable"), AX$1, "0") -> 4 | AY29: =IF(OR(O29="YES", O29="Not Applicable"), AY$1, "0") -> 4 | AZ29: =IF(OR(P29="YES", P29="Not Applicable"), AZ$1, "0") -> 2 | BA29: =IF(OR(Q29="YES", Q29="Not Applicable"), BA$1, "0") -> 4 | BB29: =IF(OR(R29="YES", R29="Not Applicable"), BB$1, "0") -> 4 | BC29: =IF(OR(S29="YES", S29="Not Applicable"), BC$1, "0") -> 4 | BD29: =IF(OR(T29="YES", T29="Not Applicable"), BD$1, "0") -> 2 | ... BY29: =IF(OR(AO29="YES", AO29="Not Applicable"), BY$1, "0") -> 0 | BZ29: =SUM(AW29:BY29) -> 96 | CA29: =VLOOKUP(J:J,'Agent wise'!A:C,3,0) -> Adharsh | CB29: =INT(E29) -> 45931 | CC29: =IF(BZ29>=94.5, "Excellent", IF(BZ29>89.5, "Good", IF(BZ29>84.5, "Average", "FC"))) -> Excellent | CJ29: =DAY(E29) -> 1 | CK29: =MONTH(E29) -> 10 | CL29: =YEAR(E29) -> 2025
A30: 45698.444 | B30: priyankajino2013@gmail.com | C30: 0 / 40 | D30: Priyanka | E30: 45932 | F30: Wireless | G30: 45667 | H30: 8330068261 | I30: 157 | J30: VPS258 | K30: Malayalam | L30: Kerala | M30: Yes | N30: Yes | O30: Yes | P30: Yes | Q30: Yes | R30: No | S30: Yes | T30: Yes | U30: No | V30: Yes | W30: Yes | X30: No | Y30: Yes | Z30: Yes | AA30: No | AB30: Not Applicable | AC30: Not Applicable | AD30: Yes | AE30: No | AF30: Yes | AG30: No | AH30: Yes | AI30: Not Applicable | AJ30: Yes | AK30: Yes | AL30: No | AM30: Yes | AN30: Yes | AO30: No | AP30: AOI-dead air,empathy missing, | AQ30: Opening & Introduction â€“ Done Customer details captured â€“Done Customer concern -Customer ask data issue Resolution shared - Advisor complete probing to customers as per call setting provide Closing as per standard - Done. AOI-dead air,empathy missing,accurent information not done | AR30: Prepaid | AS30: RECHARGE ISSUE | AT30: DOUBLE RECHARGE | AW30: =IF(OR(M30="YES", M30="Not Applicable"), AW$1, "0") -> 6 | AX30: =IF(OR(N30="YES", N30="Not Applicable"), AX$1, "0") -> 4 | AY30: =IF(OR(O30="YES", O30="Not Applicable"), AY$1, "0") -> 4 | AZ30: =IF(OR(P30="YES", P30="Not Applicable"), AZ$1, "0") -> 2 | BA30: =IF(OR(Q30="YES", Q30="Not Applicable"), BA$1, "0") -> 4 | BB30: =IF(OR(R30="YES", R30="Not Applicable"), BB$1, "0") -> 0 | BC30: =IF(OR(S30="YES", S30="Not Applicable"), BC$1, "0") -> 4 | BD30: =IF(OR(T30="YES", T30="Not Applicable"), BD$1, "0") -> 2 | ... BY30: =IF(OR(AO30="YES", AO30="Not Applicable"), BY$1, "0") -> 0 | BZ30: =SUM(AW30:BY30) -> 74 | CA30: =VLOOKUP(J:J,'Agent wise'!A:C,3,0) -> Adharsh | CB30: =INT(E30) -> 45932 | CC30: =IF(BZ30>=94.5, "Excellent", IF(BZ30>89.5, "Good", IF(BZ30>84.5, "Average", "FC"))) -> FC | CJ30: =DAY(E30) -> 2 | CK30: =MONTH(E30) -> 10 | CL30: =YEAR(E30) -> 2025
A31: 45698.452 | B31: priyankajino2013@gmail.com | C31: 0 / 40 | D31: Priyanka | E31: 45932 | F31: Wireless | G31: 45667 | H31: 8089911694 | I31: 145 | J31: SBM482 | K31: Malayalam | L31: Kerala | M31: Yes | N31: Yes | O31: Yes | P31: Yes | Q31: Yes | R31: No | S31: Yes | T31: Yes | U31: Yes | V31: Yes | W31: Yes | X31: Yes | Y31: Yes | Z31: Yes | AA31: No | AB31: Yes | AC31: Yes | AD31: Yes | AE31: Yes | AF31: Yes | AG31: Yes | AH31: Yes | AI31: Not Applicable | AJ31: Yes | AK31: Yes | AL31: Yes | AM31: Yes | AN31: Yes | AO31: Yes | AP31: AOI-empathy missing, | AQ31: Opening & Introduction â€“ Done Customer details captured â€“Done Customer concern -Customer ask recharge issue Resolution shared - Advisor complete probing to customers as per call inactive stage Closing as per standard - Done. AOI-empathy missing, | AR31: Prepaid | AS31: PLANS AND VALIDITY DETAILS | AT31: ENQUIRY ON BALANCE AND VALIDITY | AW31: =IF(OR(M31="YES", M31="Not Applicable"), AW$1, "0") -> 6 | AX31: =IF(OR(N31="YES", N31="Not Applicable"), AX$1, "0") -> 4 | AY31: =IF(OR(O31="YES", O31="Not Applicable"), AY$1, "0") -> 4 | AZ31: =IF(OR(P31="YES", P31="Not Applicable"), AZ$1, "0") -> 2 | BA31: =IF(OR(Q31="YES", Q31="Not Applicable"), BA$1, "0") -> 4 | BB31: =IF(OR(R31="YES", R31="Not Applicable"), BB$1, "0") -> 0 | BC31: =IF(OR(S31="YES", S31="Not Applicable"), BC$1, "0") -> 4 | BD31: =IF(OR(T31="YES", T31="Not Applicable"), BD$1, "0") -> 2 | ... BY31: =IF(OR(AO31="YES", AO31="Not Applicable"), BY$1, "0") -> 0 | BZ31: =SUM(AW31:BY31) -> 92 | CA31: =VLOOKUP(J:J,'Agent wise'!A:C,3,0) -> #N/A | CB31: =INT(E31) -> 45932 | CC31: =IF(BZ31>=94.5, "Excellent", IF(BZ31>89.5, "Good", IF(BZ31>84.5, "Average", "FC"))) -> Good | CJ31: =DAY(E31) -> 2 | CK31: =MONTH(E31) -> 10 | CL31: =YEAR(E31) -> 2025
A32: 45698.47 | B32: priyankajino2013@gmail.com | C32: 0 / 40 | D32: Priyanka | E32: 45932 | F32: Wireless | G32: 45667 | H32: 8056585548 | I32: 248 | J32: VPS256 | K32: Tamil | L32: Tamil Nadu | M32: No | N32: Yes | O32: Yes | P32: Yes | Q32: Yes | R32: No | S32: Yes | T32: Yes | U32: Yes | V32: Yes | W32: Yes | X32: Yes | Y32: Yes | Z32: Yes | AA32: No | AB32: Yes | AC32: Yes | AD32: Yes | AE32: Yes | AF32: Yes | AG32: No | AH32: Yes | AI32: Not Applicable | AJ32: Yes | AK32: Yes | AL32: Yes | AM32: Yes | AN32: Yes | AO32: No | AP32: AOI-empathy missing,Greeted Customer | AQ32: Opening & Introduction â€“ Done Customer details captured â€“Done Customer concern -Customer ask recharge issue Resolution shared - Advisor complete probing to customers as per call inactive stage Closing as per standard - Done. AOI-empathy missing,Greeted Customer | AR32: Prepaid | AS32: SMS SERVICES | AT32: UNABLE TO SEND SMS | AW32: =IF(OR(M32="YES", M32="Not Applicable"), AW$1, "0") -> 0 | AX32: =IF(OR(N32="YES", N32="Not Applicable"), AX$1, "0") -> 4 | AY32: =IF(OR(O32="YES", O32="Not Applicable"), AY$1, "0") -> 4 | AZ32: =IF(OR(P32="YES", P32="Not Applicable"), AZ$1, "0") -> 2 | BA32: =IF(OR(Q32="YES", Q32="Not Applicable"), BA$1, "0") -> 4 | BB32: =IF(OR(R32="YES", R32="Not Applicable"), BB$1, "0") -> 0 | BC32: =IF(OR(S32="YES", S32="Not Applicable"), BC$1, "0") -> 4 | BD32: =IF(OR(T32="YES", T32="Not Applicable"), BD$1, "0") -> 2 | ... BY32: =IF(OR(AO32="YES", AO32="Not Applicable"), BY$1, "0") -> 0 | BZ32: =SUM(AW32:BY32) -> 80 | CA32: =VLOOKUP(J:J,'Agent wise'!A:C,3,0) -> Saran S | CB32: =INT(E32) -> 45932 | CC32: =IF(BZ32>=94.5, "Excellent", IF(BZ32>89.5, "Good", IF(BZ32>84.5, "Average", "FC"))) -> FC | CJ32: =DAY(E32) -> 2 | CK32: =MONTH(E32) -> 10 | CL32: =YEAR(E32) -> 2025
A33: 45698.478 | B33: priyankajino2013@gmail.com | C33: 0 / 40 | D33: Priyanka | E33: 45932 | F33: Wireless | G33: 45667 | H33: 9400647054 | I33: 161 | J33: VPS253 | K33: Malayalam | L33: Kerala | M33: Yes | N33: Yes | O33: Yes | P33: Yes | Q33: Yes | R33: No | S33: Yes | T33: Yes | U33: Yes | V33: Yes | W33: Yes | X33: Yes | Y33: Yes | Z33: Yes | AA33: No | AB33: Yes | AC33: Yes | AD33: Yes | AE33: Yes | AF33: Yes | AG33: Yes | AH33: Yes | AI33: Yes | AJ33: Yes | AK33: Yes | AL33: Yes | AM33: Yes | AN33: Yes | AO33: Yes | AP33: AOI-empathy missing, | AQ33: Opening & Introduction â€“ Done Customer details captured â€“Done Customer concern -Customer ask sim converted Resolution shared - Advisor complete probing to customers as per call unified sim Closing as per standard - Done. AOI-empathy missing, | AR33: Prepaid | AS33: SIM | AT33: NEW SIM ACTIVATION PROCESS | AW33: =IF(OR(M33="YES", M33="Not Applicable"), AW$1, "0") -> 6 | AX33: =IF(OR(N33="YES", N33="Not Applicable"), AX$1, "0") -> 4 | AY33: =IF(OR(O33="YES", O33="Not Applicable"), AY$1, "0") -> 4 | AZ33: =IF(OR(P33="YES", P33="Not Applicable"), AZ$1, "0") -> 2 | BA33: =IF(OR(Q33="YES", Q33="Not Applicable"), BA$1, "0") -> 4 | BB33: =IF(OR(R33="YES", R33="Not Applicable"), BB$1, "0") -> 0 | BC33: =IF(OR(S33="YES", S33="Not Applicable"), BC$1, "0") -> 4 | BD33: =IF(OR(T33="YES", T33="Not Applicable"), BD$1, "0") -> 2 | ... BY33: =IF(OR(AO33="YES", AO33="Not Applicable"), BY$1, "0") -> 0 | BZ33: =SUM(AW33:BY33) -> 92 | CA33: =VLOOKUP(J:J,'Agent wise'!A:C,3,0) -> Adharsh | CB33: =INT(E33) -> 45932 | CC33: =IF(BZ33>=94.5, "Excellent", IF(BZ33>89.5, "Good", IF(BZ33>84.5, "Average", "FC"))) -> Good | CJ33: =DAY(E33) -> 2 | CK33: =MONTH(E33) -> 10 | CL33: =YEAR(E33) -> 2025
A34: 45698.479 | B34: adharshleewvan003@gmail.com | C34: 0 / 40 | D34: Adharsh | E34: 45931 | F34: MNP OBD | G34: 9/30/2025 | H34: 9894713944 | I34: 198 | J34: SBM744 | K34: Tamil | L34: Tamil Nadu | M34: Yes | N34: Yes | O34: Yes | P34: Yes | Q34: Yes | R34: Yes | S34: Yes | T34: Yes | U34: Yes | V34: Yes | W34: Yes | X34: Yes | Y34: Yes | Z34: Yes | AA34: Yes | AB34: Yes | AC34: Yes | AD34: Yes | AE34: No | AF34: Yes | AG34: Yes | AH34: Yes | AI34: Not Applicable | AJ34: Yes | AK34: Yes | AL34: Yes | AM34: Yes | AN34: Yes | AO34: No | AP34: Maintained focus on caller's problem, Tagging Accuracy | AQ34: Reason for PORTING request: Network issue Resolution provided: Complaint not taken, customer requested for call back | AR34: Prepaid | AS34: INCOMPLETE CALL | AT34: DISCONNECTED BY CUSTOMER | AW34: =IF(OR(M34="YES", M34="Not Applicable"), AW$1, "0") -> 6 | AX34: =IF(OR(N34="YES", N34="Not Applicable"), AX$1, "0") -> 4 | AY34: =IF(OR(O34="YES", O34="Not Applicable"), AY$1, "0") -> 4 | AZ34: =IF(OR(P34="YES", P34="Not Applicable"), AZ$1, "0") -> 2 | BA34: =IF(OR(Q34="YES", Q34="Not Applicable"), BA$1, "0") -> 4 | BB34: =IF(OR(R34="YES", R34="Not Applicable"), BB$1, "0") -> 4 | BC34: =IF(OR(S34="YES", S34="Not Applicable"), BC$1, "0") -> 4 | BD34: =IF(OR(T34="YES", T34="Not Applicable"), BD$1, "0") -> 2 | ... BY34: =IF(OR(AO34="YES", AO34="Not Applicable"), BY$1, "0") -> 0 | BZ34: =SUM(AW34:BY34) -> 96 | CA34: =VLOOKUP(J:J,'Agent wise'!A:C,3,0) -> Shiny | CB34: =INT(E34) -> 45931 | CC34: =IF(BZ34>=94.5, "Excellent", IF(BZ34>89.5, "Good", IF(BZ34>84.5, "Average", "FC"))) -> Excellent | CJ34: =DAY(E34) -> 1 | CK34: =MONTH(E34) -> 10 | CL34: =YEAR(E34) -> 2025
A35: 45698.496 | B35: priyankajino2013@gmail.com | C35: 0 / 40 | D35: Priyanka | E35: 45932 | F35: Wireless | G35: 45667 | H35: 8943722655 | I35: 163 | J35: VPS252 | K35: Malayalam | L35: Kerala | M35: Yes | N35: Yes | O35: Yes | P35: Yes | Q35: Yes | R35: No | S35: Yes | T35: Yes | U35: Yes | V35: Yes | W35: Yes | X35: Yes | Y35: Yes | Z35: Yes | AA35: No | AB35: Yes | AC35: No | AD35: Yes | AE35: Yes | AF35: Yes | AG35: No | AH35: Yes | AI35: Not Applicable | AJ35: Yes | AK35: Yes | AL35: Yes | AM35: Yes | AN35: Yes | AO35: Yes | AP35: AOI-empathy missing, probing not done,dead air | AQ35: Opening & Introduction â€“ Done Customer details captured â€“Done Customer concern -Customer ask sim converted Resolution shared - Advisor complete probing to customers as per call sim deactive Closing as per standard - Done. AOI-empathy missing, probing not done,dead air | AR35: Prepaid | AS35: SIM | AT35: SIM REPLACEMENT PROCESS | AW35: =IF(OR(M35="YES", M35="Not Applicable"), AW$1, "0") -> 6 | AX35: =IF(OR(N35="YES", N35="Not Applicable"), AX$1, "0") -> 4 | AY35: =IF(OR(O35="YES", O35="Not Applicable"), AY$1, "0") -> 4 | AZ35: =IF(OR(P35="YES", P35="Not Applicable"), AZ$1, "0") -> 2 | BA35: =IF(OR(Q35="YES", Q35="Not Applicable"), BA$1, "0") -> 4 | BB35: =IF(OR(R35="YES", R35="Not Applicable"), BB$1, "0") -> 0 | BC35: =IF(OR(S35="YES", S35="Not Applicable"), BC$1, "0") -> 4 | BD35: =IF(OR(T35="YES", T35="Not Applicable"), BD$1, "0") -> 2 | ... BY35: =IF(OR(AO35="YES", AO35="Not Applicable"), BY$1, "0") -> 0 | BZ35: =SUM(AW35:BY35) -> 82 | CA35: =VLOOKUP(J:J,'Agent wise'!A:C,3,0) -> Shiny | CB35: =INT(E35) -> 45932 | CC35: =IF(BZ35>=94.5, "Excellent", IF(BZ35>89.5, "Good", IF(BZ35>84.5, "Average", "FC"))) -> FC | CJ35: =DAY(E35) -> 2 | CK35: =MONTH(E35) -> 10 | CL35: =YEAR(E35) -> 2025
A36: 45698.503 | B36: adharshleewvan003@gmail.com | C36: 0 / 40 | D36: Adharsh | E36: 45932 | F36: MNP OBD | G36: 45667 | H36: 9487716094 | I36: 196 | J36: SBM554 | K36: Tamil | L36: Tamil Nadu | M36: Yes | N36: Yes | O36: Yes | P36: Yes | Q36: Yes | R36: Yes | S36: Yes | T36: Yes | U36: Yes | V36: Yes | W36: Yes | X36: Yes | Y36: Yes | Z36: Yes | AA36: Yes | AB36: Yes | AC36: Yes | AD36: Yes | AE36: Yes | AF36: Yes | AG36: Yes | AH36: Not Applicable | AI36: Not Applicable | AJ36: Yes | AK36: Yes | AL36: Yes | AM36: Yes | AN36: Yes | AO36: Yes | AP36: Good call | AQ36: Reason for PORTING request: Network issue Resolution provided: Complaint not taken, customer requested for call back | AR36: Prepaid | AS36: CALL BACK | AT36: REQUESTED TO CALLBACK | AW36: =IF(OR(M36="YES", M36="Not Applicable"), AW$1, "0") -> 6 | AX36: =IF(OR(N36="YES", N36="Not Applicable"), AX$1, "0") -> 4 | AY36: =IF(OR(O36="YES", O36="Not Applicable"), AY$1, "0") -> 4 | AZ36: =IF(OR(P36="YES", P36="Not Applicable"), AZ$1, "0") -> 2 | BA36: =IF(OR(Q36="YES", Q36="Not Applicable"), BA$1, "0") -> 4 | BB36: =IF(OR(R36="YES", R36="Not Applicable"), BB$1, "0") -> 4 | BC36: =IF(OR(S36="YES", S36="Not Applicable"), BC$1, "0") -> 4 | BD36: =IF(OR(T36="YES", T36="Not Applicable"), BD$1, "0") -> 2 | ... BY36: =IF(OR(AO36="YES", AO36="Not Applicable"), BY$1, "0") -> 0 | BZ36: =SUM(AW36:BY36) -> 100 | CA36: =VLOOKUP(J:J,'Agent wise'!A:C,3,0) -> Adharsh | CB36: =INT(E36) -> 45932 | CC36: =IF(BZ36>=94.5, "Excellent", IF(BZ36>89.5, "Good", IF(BZ36>84.5, "Average", "FC"))) -> Excellent | CJ36: =DAY(E36) -> 2 | CK36: =MONTH(E36) -> 10 | CL36: =YEAR(E36) -> 2025
A37: 45698.504 | B37: priyankajino2013@gmail.com | C37: 0 / 40 | D37: Priyanka | E37: 45932 | F37: Wireless | G37: 45667 | H37: 8330047076 | I37: 188 | J37: VPS251 | K37: Malayalam | L37: Kerala | M37: Yes | N37: Yes | O37: Yes | P37: Yes | Q37: Yes | R37: No | S37: No | T37: Yes | U37: Yes | V37: Yes | W37: Yes | X37: Yes | Y37: Yes | Z37: Yes | AA37: No | AB37: Yes | AC37: No | AD37: Yes | AE37: Yes | AF37: Yes | AG37: Yes | AH37: Yes | AI37: Not Applicable | AJ37: Yes | AK37: Yes | AL37: Yes | AM37: Yes | AN37: Yes | AO37: No | AP37: AOI-empathy missing,dead air, | AQ37: Opening & Introduction â€“ Done Customer details captured â€“Done Customer concern -Customer ask data issue Resolution shared - Advisor complete probing to customers as per call setting provide Closing as per standard - Done. AOI-empathy missing,dead air, | AR37: Prepaid | AS37: DATA SERVICES | AT37: UNABLE TO BROWSE DATA | AW37: =IF(OR(M37="YES", M37="Not Applicable"), AW$1, "0") -> 6 | AX37: =IF(OR(N37="YES", N37="Not Applicable"), AX$1, "0") -> 4 | AY37: =IF(OR(O37="YES", O37="Not Applicable"), AY$1, "0") -> 4 | AZ37: =IF(OR(P37="YES", P37="Not Applicable"), AZ$1, "0") -> 2 | BA37: =IF(OR(Q37="YES", Q37="Not Applicable"), BA$1, "0") -> 4 | BB37: =IF(OR(R37="YES", R37="Not Applicable"), BB$1, "0") -> 0 | BC37: =IF(OR(S37="YES", S37="Not Applicable"), BC$1, "0") -> 0 | BD37: =IF(OR(T37="YES", T37="Not Applicable"), BD$1, "0") -> 2 | ... BY37: =IF(OR(AO37="YES", AO37="Not Applicable"), BY$1, "0") -> 0 | BZ37: =SUM(AW37:BY37) -> 84 | CA37: =VLOOKUP(J:J,'Agent wise'!A:C,3,0) -> Shakeer | CB37: =INT(E37) -> 45932 | CC37: =IF(BZ37>=94.5, "Excellent", IF(BZ37>89.5, "Good", IF(BZ37>84.5, "Average", "FC"))) -> FC | CJ37: =DAY(E37) -> 2 | CK37: =MONTH(E37) -> 10 | CL37: =YEAR(E37) -> 2025
A38: 45698.519 | B38: priyankajino2013@gmail.com | C38: 0 / 50 | D38: Priyanka | E38: 45932 | F38: Wireless | G38: 45667 | H38: 8281797484 | I38: 141 | J38: VPS249 | K38: Malayalam | L38: Kerala | M38: Yes | N38: Yes | O38: Yes | P38: Yes | Q38: Yes | R38: No | S38: Yes | T38: Yes | U38: Yes | V38: Yes | W38: Yes | X38: Yes | Y38: Yes | Z38: Yes | AA38: No | AB38: Yes | AC38: Yes | AD38: Yes | AE38: Yes | AF38: Yes | AG38: Yes | AH38: Yes | AI38: Not Applicable | AJ38: Yes | AK38: Yes | AL38: Yes | AM38: Yes | AN38: Yes | AO38: Yes | AP38: AOI-empathy missing,probing not done | AQ38: Opening & Introduction â€“ Done Customer details captured â€“Done Customer concern -Customer ask network issue Resolution shared - Advisor complete probing to customers as per call setting provide Closing as per standard - Done. AOI-empathy missing,probing not done | AR38: Prepaid | AS38: SIM | AT38: REPLACED SIM NOT ACTIVATED | AU38: Good Call | AW38: =IF(OR(M38="YES", M38="Not Applicable"), AW$1, "0") -> 6 | AX38: =IF(OR(N38="YES", N38="Not Applicable"), AX$1, "0") -> 4 | AY38: =IF(OR(O38="YES", O38="Not Applicable"), AY$1, "0") -> 4 | AZ38: =IF(OR(P38="YES", P38="Not Applicable"), AZ$1, "0") -> 2 | BA38: =IF(OR(Q38="YES", Q38="Not Applicable"), BA$1, "0") -> 4 | BB38: =IF(OR(R38="YES", R38="Not Applicable"), BB$1, "0") -> 0 | BC38: =IF(OR(S38="YES", S38="Not Applicable"), BC$1, "0") -> 4 | BD38: =IF(OR(T38="YES", T38="Not Applicable"), BD$1, "0") -> 2 | ... BY38: =IF(OR(AO38="YES", AO38="Not Applicable"), BY$1, "0") -> 0 | BZ38: =SUM(AW38:BY38) -> 92 | CA38: =VLOOKUP(J:J,'Agent wise'!A:C,3,0) -> Adharsh | CB38: =INT(E38) -> 45932 | CC38: =IF(BZ38>=94.5, "Excellent", IF(BZ38>89.5, "Good", IF(BZ38>84.5, "Average", "FC"))) -> Good | CJ38: =DAY(E38) -> 2 | CK38: =MONTH(E38) -> 10 | CL38: =YEAR(E38) -> 2025
